<?xml version="1.0"?>
<robot xmlns:xacro="http://www.ros.org/wiki/xacro">

  <xacro:property name="wheel_radius" value="0.1"/>
  <xacro:property name="wheel_width" value="0.05"/>
  <xacro:property name="wheel_separation" value="0.5"/> <!-- base_width 0.45 + width 0.05 -->
  <xacro:property name="wheel_x_offset" value="-0.15"/>
  <xacro:property name="wheel_z_offset" value="-0.05"/> <!-- 0.15 (base_link) - 0.10 (wheel radius) = 0.05 -->
  
  <material name="black">
    <color rgba="0.1 0.1 0.1 1"/>
  </material>

  <xacro:macro name="drive_wheel" params="prefix y_reflect">
    <link name="${prefix}_wheel_link">
      <visual>
        <origin xyz="0 0 0" rpy="${pi/2} 0 0"/>
        <geometry>
          <cylinder radius="${wheel_radius}" length="${wheel_width}"/>
        </geometry>
        <material name="black"/>
      </visual>
      <collision>
        <origin xyz="0 0 0" rpy="${pi/2} 0 0"/>
        <geometry>
          <cylinder radius="${wheel_radius}" length="${wheel_width}"/>
        </geometry>
      </collision>
      <inertial>
        <origin xyz="0 0 0" rpy="${pi/2} 0 0"/>
        <mass value="1.0"/>
        <inertia ixx="0.01" ixy="0.0" ixz="0.0" iyy="0.01" iyz="0.0" izz="0.01"/>
      </inertial>
    </link>

    <joint name="${prefix}_wheel_joint" type="continuous">
      <parent link="base_link"/>
      <child link="${prefix}_wheel_link"/>
      <origin xyz="${wheel_x_offset} ${y_reflect * wheel_separation / 2} ${wheel_z_offset}" rpy="0 0 0"/>
      <axis xyz="0 1 0"/>
    </joint>
  </xacro:macro>

  <xacro:drive_wheel prefix="left" y_reflect="1"/>
  <xacro:drive_wheel prefix="right" y_reflect="-1"/>

  <!-- Caster Wheel -->
  <xacro:property name="caster_radius" value="0.05"/>
  <xacro:property name="caster_x_offset" value="0.2"/>
  <xacro:property name="caster_z_offset" value="-0.1"/> <!-- 0.15 (base_link) - 0.05 (caster radius) = 0.10 -->

  <link name="caster_wheel_link">
    <visual>
      <origin xyz="0 0 0" rpy="0 0 0"/>
      <geometry>
        <sphere radius="${caster_radius}"/>
      </geometry>
      <material name="black"/>
    </visual>
    <collision>
      <origin xyz="0 0 0" rpy="0 0 0"/>
      <geometry>
        <sphere radius="${caster_radius}"/>
      </geometry>
    </collision>
    <inertial>
      <origin xyz="0 0 0" rpy="0 0 0"/>
      <mass value="0.5"/>
      <inertia ixx="0.001" ixy="0.0" ixz="0.0" iyy="0.001" iyz="0.0" izz="0.001"/>
    </inertial>
  </link>

  <joint name="caster_wheel_joint" type="fixed">
    <parent link="base_link"/>
    <child link="caster_wheel_link"/>
    <origin xyz="${caster_x_offset} 0 ${caster_z_offset}" rpy="0 0 0"/>
  </joint>

</robot>
